Workbook

Sheet Main Project Raw Data
A1: Employee_ID | B1: First_Name | C1: Last_Name | D1: Age | E1: Department_Region | F1: Status | G1: Join_Date | H1: Salary | I1: Email | J1: Phone | K1: Performance_Score | L1: Remote_Work
A2: EMP1000 | B2: Bob | C2: Davis | D2: 25 | E2: DevOps-California | F2: Active | G2: 44231 | H2: 59767.65 | I2: bob.davis@example.com | J2: -1651623197 | K2: Average | L2: TRUE
A3: EMP1001 | B3: Bob | C3: Brown | E3: Finance-Texas | F3: Active | G3: 44111 | H3: 65304.66 | I3: bob.brown@example.com | J3: -1898471390 | K3: Excellent | L3: TRUE
A4: EMP1002 | B4: Alice | C4: Jones | E4: Admin-Nevada | F4: Pending | G4: 45119 | H4: 88145.9 | I4: alice.jones@example.com | J4: -5596363211 | K4: Good | L4: TRUE
A5: EMP1003 | B5: Eva | C5: Davis | D5: 25 | E5: Admin-Nevada | F5: Inactive | G5: 11/27/2021 | H5: 69450.99 | I5: eva.davis@example.com | J5: -3476490784 | K5: Good | L5: TRUE
A6: EMP1004 | B6: Frank | C6: Williams | D6: 25 | E6: Cloud Tech-Florida | F6: Active | G6: 44682 | H6: 109324.61 | I6: frank.williams@example.com | J6: -1586734256 | K6: Poor | L6: FALSE
A7: EMP1005 | B7: Alice | C7: Garcia | D7: 40 | E7: Sales-Texas | F7: Inactive | G7: 44110 | H7: 88642.84 | I7: alice.garcia@example.com | J7: -5409003485 | K7: Good | L7: FALSE
A8: EMP1006 | B8: Frank | C8: Jones | E8: Admin-Nevada | F8: Active | G8: 43894 | H8: 96288.43 | I8: frank.jones@example.com | J8: -4518376063 | K8: Good | L8: FALSE
A9: EMP1007 | B9: Bob | C9: Jones | D9: 30 | E9: Cloud Tech-Florida | F9: Inactive | G9: 7/17/2022 | H9: 94497.91 | I9: bob.jones@example.com | J9: -4134327559 | K9: Average | L9: TRUE
A10: EMP1008 | B10: Frank | C10: Davis | D10: 35 | E10: Admin-Nevada | F10: Inactive | G10: 45150 | H10: 115565.82 | I10: frank.davis@example.com | J10: -4177656123 | K10: Excellent | L10: TRUE
A11: EMP1009 | B11: Charlie | C11: Johnson | E11: DevOps-New York | F11: Active | G11: 44659 | H11: 76561.88 | I11: charlie.johnson@example.com | J11: -8156985699 | K11: Excellent | L11: TRUE
A12: EMP1010 | B12: David | C12: Williams | D12: 35 | E12: Cloud Tech-New York | F12: Active | G12: 45450 | H12: 72081.71 | I12: david.williams@example.com | J12: -2720634590 | K12: Average | L12: FALSE
A13: EMP1011 | B13: David | C13: Davis | E13: DevOps-California | F13: Active | G13: 45025 | H13: 84946.19 | I13: david.davis@example.com | J13: -1238296576 | K13: Poor | L13: TRUE
A14: EMP1012 | B14: Heidi | C14: Williams | D14: 30 | E14: HR-New York | F14: Active | G14: 45415 | H14: 89295.77 | I14: heidi.williams@example.com | J14: -2429543164 | K14: Excellent | L14: FALSE
A15: EMP1013 | B15: Grace | C15: Williams | E15: Finance-California | F15: Active | G15: 44114 | H15: 85666.84 | I15: grace.williams@example.com | J15: -2669300892 | K15: Good | L15: FALSE
A16: EMP1014 | B16: Alice | C16: Garcia | D16: 25 | E16: Admin-Nevada | F16: Active | G16: 45571 | H16: 97633.68 | I16: alice.garcia@example.com | J16: -1734206968 | K16: Excellent | L16: TRUE
A17: EMP1015 | B17: Grace | C17: Jones | D17: 40 | E17: Sales-Florida | F17: Pending | G17: 5/29/2021 | H17: 117975.49 | I17: grace.jones@example.com | J17: -4215291085 | K17: Good | L17: TRUE
A18: EMP1016 | B18: Alice | C18: Brown | D18: 25 | E18: DevOps-Illinois | F18: Inactive | G18: 4/23/2024 | H18: 94867.33 | I18: alice.brown@example.com | J18: -7713334475 | K18: Poor | L18: FALSE
A19: EMP1017 | B19: Grace | C19: Garcia | D19: 30 | E19: Finance-Texas | F19: Pending | G19: 11/28/2024 | H19: 100377.65 | I19: grace.garcia@example.com | J19: -2639343625 | K19: Average | L19: TRUE
A20: EMP1018 | B20: Charlie | C20: Garcia | E20: Cloud Tech-Nevada | F20: Inactive | G20: 9/19/2024 | H20: 94726.46 | I20: charlie.garcia@example.com | J20: -2044397358 | K20: Excellent | L20: FALSE
A21: EMP1019 | B21: Charlie | C21: Williams | D21: 35 | E21: Admin-Illinois | F21: Pending | G21: 43862 | H21: 91926.12 | I21: charlie.williams@example.com | J21: -7107256365 | K21: Average | L21: TRUE
A22: EMP1020 | B22: Bob | C22: Miller | D22: 35 | E22: HR-New York | F22: Active | G22: 44413 | H22: 111460.67 | I22: bob.miller@example.com | J22: -9411800536 | K22: Excellent | L22: TRUE
A23: EMP1021 | B23: Bob | C23: Jones | D23: 40 | E23: Cloud Tech-Illinois | F23: Active | G23: 9/19/2020 | H23: 96182.56 | I23: bob.jones@example.com | J23: -5990048963 | K23: Good | L23: FALSE
A24: EMP1022 | B24: Charlie | C24: Johnson | D24: 35 | E24: Sales-Illinois | F24: Inactive | G24: 44442 | H24: 115023.94 | I24: charlie.johnson@example.com | J24: -6528092427 | K24: Average | L24: TRUE
A25: EMP1023 | B25: David | C25: Garcia | D25: 35 | E25: Finance-Nevada | F25: Pending | G25: 44622 | H25: 80667.01 | I25: david.garcia@example.com | J25: -7572158623 | K25: Excellent | L25: FALSE
A26: EMP1024 | B26: Bob | C26: Brown | D26: 30 | E26: Admin-Texas | F26: Inactive | G26: 2/13/2020 | H26: 91181.61 | I26: bob.brown@example.com | J26: -1502745643 | K26: Good | L26: TRUE
A27: EMP1025 | B27: David | C27: Miller | D27: 25 | E27: Cloud Tech-Nevada | F27: Pending | G27: 4/30/2020 | H27: 66025.92 | I27: david.miller@example.com | J27: -9485625727 | K27: Average | L27: FALSE
A28: EMP1026 | B28: Frank | C28: Miller | D28: 25 | E28: Sales-New York | F28: Inactive | G28: 44967 | H28: 83979.01 | I28: frank.miller@example.com | J28: -7032032073 | K28: Average | L28: FALSE
A29: EMP1027 | B29: Heidi | C29: Johnson | D29: 30 | E29: Finance-Florida | F29: Active | G29: 44172 | H29: 56785.16 | I29: heidi.johnson@example.com | J29: -2761707586 | K29: Excellent | L29: TRUE
A30: EMP1028 | B30: Grace | C30: Garcia | D30: 40 | E30: Finance-Nevada | F30: Active | G30: 45240 | H30: 95741.88 | I30: grace.garcia@example.com | J30: -7712151341 | K30: Excellent | L30: FALSE
A31: EMP1029 | B31: Alice | C31: Brown | D31: 40 | E31: DevOps-California | F31: Active | G31: 5/24/2021 | H31: 63411.31 | I31: alice.brown@example.com | J31: -2849939088 | K31: Excellent | L31: TRUE
A32: EMP1030 | B32: Charlie | C32: Jones | D32: 40 | E32: Admin-California | F32: Inactive | G32: 5/26/2021 | H32: 111214.02 | I32: charlie.jones@example.com | J32: -2613715040 | K32: Good | L32: TRUE
A33: EMP1031 | B33: Bob | C33: Smith | D33: 25 | E33: DevOps-Illinois | F33: Active | G33: 44111 | H33: 114845.69 | I33: bob.smith@example.com | J33: -6591520176 | K33: Excellent | L33: TRUE
A34: EMP1032 | B34: Charlie | C34: Brown | D34: 40 | E34: Finance-Florida | F34: Active | G34: 45423 | H34: 78072.82 | I34: charlie.brown@example.com | J34: -7490509758 | K34: Average | L34: FALSE
A35: EMP1033 | B35: Grace | C35: Johnson | D35: 25 | E35: Finance-California | F35: Inactive | G35: 44385 | H35: 79610.52 | I35: grace.johnson@example.com | J35: -2304501895 | K35: Average | L35: FALSE
A36: EMP1034 | B36: Heidi | C36: Miller | D36: 30 | E36: Admin-California | F36: Active | G36: 4/29/2020 | H36: 90542.62 | I36: heidi.miller@example.com | J36: -1642361031 | K36: Excellent | L36: TRUE
A37: EMP1035 | B37: Frank | C37: Jones | D37: 25 | E37: Cloud Tech-Illinois | F37: Inactive | G37: 10/26/2022 | H37: 114357.1 | I37: frank.jones@example.com | J37: -6642147648 | K37: Excellent | L37: TRUE
A38: EMP1036 | B38: Alice | C38: Brown | E38: Cloud Tech-New York | F38: Active | G38: 44990 | H38: 54757.26 | I38: alice.brown@example.com | J38: -2515837766 | K38: Poor | L38: FALSE
A39: EMP1037 | B39: Grace | C39: Smith | D39: 25 | E39: Sales-New York | F39: Pending | G39: 44962 | H39: 52781.92 | I39: grace.smith@example.com | J39: -4996165925 | K39: Average | L39: TRUE
A40: EMP1038 | B40: Frank | C40: Smith | D40: 35 | E40: Admin-Nevada | F40: Pending | G40: 44326 | H40: 66708.02 | I40: frank.smith@example.com | J40: -6108573277 | K40: Good | L40: TRUE
...

Sheet Cleaning Data 
A1: Employee_ID | B1: First_Name | C1: Last_Name | D1: Age | E1: Department_Region | F1: Status | G1: Join_Date | H1: Salary | I1: Email | J1: Phone | K1: Performance_Score | L1: Remote_Work | M1: Full Name | N1: Join_Month | O1: Join_Year | P1: Department | Q1: Region
A2: =TRIM(Table1[[#This Row],[Employee_ID]]) -> EMP1000 | B2: =PROPER(TRIM(Table1[[#This Row],[First_Name]])) -> Bob | C2: =PROPER(TRIM(Table1[[#This Row],[Last_Name]])) -> Davis | D2: =IF(Table1[[#This Row],[Age]]="",AVERAGE(Table1[Age]),Table1[[#This Row],[Age]]) -> 25 | E2: DevOps-California | F2: Active | G2: =IF(ISNUMBER('Main Project Raw Data'!G2),'Main Project Raw Data'!G2,IF(ISNUMBER(SEARCH("/",'Main Project Raw Data'!G2)),DATE(RIGHT('Main Project Raw Data'!G2,4),LEFT('Main Project Raw Data'!G2,FIND("/",'Main Project Raw Data'!G2)-1),MID('Main Project Raw Data'!G2,FIND("/",'Main Project Raw Data'!G2)+1,2)),DATE(RIGHT('Main Project Raw Data'!G2,4),MID('Main Project Raw Data'!G2,4,2),LEFT('Main Project Raw Data'!G2,2)))) -> 44231 | H2: =IF(Table1[[#This Row],[Salary]]="",AVERAGE(Table1[Salary]),Table1[[#This Row],[Salary]]) -> 59767.65 | I2: =LOWER(TRIM(Table1[[#This Row],[Email]])) -> bob.davis@example.com | J2: =ABS(Table1[[#This Row],[Phone]]) -> 1651623197 | K2: =PROPER(TRIM(Table1[[#This Row],[Performance_Score]])) -> Average | L2: =Table1[[#This Row],[Remote_Work]] -> TRUE | M2: =PROPER(CONCATENATE(Table13[[#This Row],[First_Name]], Table13[[#This Row],[Last_Name]])) -> Bobdavis | N2: =TEXT(G2,"mmm") -> Feb | O2: =TEXT(Table13[[#This Row],[Join_Date]],"yyyy") -> 2021 | P2: =LEFT('Main Project Raw Data'!E2,FIND("-",'Main Project Raw Data'!E2)-1) -> DevOps | Q2: =RIGHT('Main Project Raw Data'!E2,LEN('Main Project Raw Data'!E2)-FIND("-",'Main Project Raw Data'!E2)) -> California
A3: =TRIM(Table1[[#This Row],[Employee_ID]]) -> EMP1001 | B3: =PROPER(TRIM(Table1[[#This Row],[First_Name]])) -> Bob | C3: =PROPER(TRIM(Table1[[#This Row],[Last_Name]])) -> Brown | D3: =IF(Table1[[#This Row],[Age]]="",AVERAGE(Table1[Age]),Table1[[#This Row],[Age]]) -> 32.484549 | E3: Finance-Texas | F3: Active | G3: =IF(ISNUMBER('Main Project Raw Data'!G3),'Main Project Raw Data'!G3,IF(ISNUMBER(SEARCH("/",'Main Project Raw Data'!G3)),DATE(RIGHT('Main Project Raw Data'!G3,4),LEFT('Main Project Raw Data'!G3,FIND("/",'Main Project Raw Data'!G3)-1),MID('Main Project Raw Data'!G3,FIND("/",'Main Project Raw Data'!G3)+1,2)),DATE(RIGHT('Main Project Raw Data'!G3,4),MID('Main Project Raw Data'!G3,4,2),LEFT('Main Project Raw Data'!G3,2)))) -> 44111 | H3: =IF(Table1[[#This Row],[Salary]]="",AVERAGE(Table1[Salary]),Table1[[#This Row],[Salary]]) -> 65304.66 | I3: =LOWER(TRIM(Table1[[#This Row],[Email]])) -> bob.brown@example.com | J3: =ABS(Table1[[#This Row],[Phone]]) -> 1898471390 | K3: =PROPER(TRIM(Table1[[#This Row],[Performance_Score]])) -> Excellent | L3: =Table1[[#This Row],[Remote_Work]] -> TRUE | M3: =PROPER(CONCATENATE(Table13[[#This Row],[First_Name]], Table13[[#This Row],[Last_Name]])) -> Bobbrown | N3: =TEXT(G3,"mmm") -> Oct | O3: =TEXT(Table13[[#This Row],[Join_Date]],"yyyy") -> 2020 | P3: =LEFT('Main Project Raw Data'!E3,FIND("-",'Main Project Raw Data'!E3)-1) -> Finance | Q3: =RIGHT('Main Project Raw Data'!E3,LEN('Main Project Raw Data'!E3)-FIND("-",'Main Project Raw Data'!E3)) -> Texas
A4: =TRIM(Table1[[#This Row],[Employee_ID]]) -> EMP1002 | B4: =PROPER(TRIM(Table1[[#This Row],[First_Name]])) -> Alice | C4: =PROPER(TRIM(Table1[[#This Row],[Last_Name]])) -> Jones | D4: =IF(Table1[[#This Row],[Age]]="",AVERAGE(Table1[Age]),Table1[[#This Row],[Age]]) -> 32.484549 | E4: Admin-Nevada | F4: Pending | G4: =IF(ISNUMBER('Main Project Raw Data'!G4),'Main Project Raw Data'!G4,IF(ISNUMBER(SEARCH("/",'Main Project Raw Data'!G4)),DATE(RIGHT('Main Project Raw Data'!G4,4),LEFT('Main Project Raw Data'!G4,FIND("/",'Main Project Raw Data'!G4)-1),MID('Main Project Raw Data'!G4,FIND("/",'Main Project Raw Data'!G4)+1,2)),DATE(RIGHT('Main Project Raw Data'!G4,4),MID('Main Project Raw Data'!G4,4,2),LEFT('Main Project Raw Data'!G4,2)))) -> 45119 | H4: =IF(Table1[[#This Row],[Salary]]="",AVERAGE(Table1[Salary]),Table1[[#This Row],[Salary]]) -> 88145.9 | I4: =LOWER(TRIM(Table1[[#This Row],[Email]])) -> alice.jones@example.com | J4: =ABS(Table1[[#This Row],[Phone]]) -> 5596363211 | K4: =PROPER(TRIM(Table1[[#This Row],[Performance_Score]])) -> Good | L4: =Table1[[#This Row],[Remote_Work]] -> TRUE | M4: =PROPER(CONCATENATE(Table13[[#This Row],[First_Name]], Table13[[#This Row],[Last_Name]])) -> Alicejones | N4: =TEXT(G4,"mmm") -> Jul | O4: =TEXT(Table13[[#This Row],[Join_Date]],"yyyy") -> 2023 | P4: =LEFT('Main Project Raw Data'!E4,FIND("-",'Main Project Raw Data'!E4)-1) -> Admin | Q4: =RIGHT('Main Project Raw Data'!E4,LEN('Main Project Raw Data'!E4)-FIND("-",'Main Project Raw Data'!E4)) -> Nevada
A5: =TRIM(Table1[[#This Row],[Employee_ID]]) -> EMP1003 | B5: =PROPER(TRIM(Table1[[#This Row],[First_Name]])) -> Eva | C5: =PROPER(TRIM(Table1[[#This Row],[Last_Name]])) -> Davis | D5: =IF(Table1[[#This Row],[Age]]="",AVERAGE(Table1[Age]),Table1[[#This Row],[Age]]) -> 25 | E5: Admin-Nevada | F5: Inactive | G5: =IF(ISNUMBER('Main Project Raw Data'!G5),'Main Project Raw Data'!G5,IF(ISNUMBER(SEARCH("/",'Main Project Raw Data'!G5)),DATE(RIGHT('Main Project Raw Data'!G5,4),LEFT('Main Project Raw Data'!G5,FIND("/",'Main Project Raw Data'!G5)-1),MID('Main Project Raw Data'!G5,FIND("/",'Main Project Raw Data'!G5)+1,2)),DATE(RIGHT('Main Project Raw Data'!G5,4),MID('Main Project Raw Data'!G5,4,2),LEFT('Main Project Raw Data'!G5,2)))) -> 44527 | H5: =IF(Table1[[#This Row],[Salary]]="",AVERAGE(Table1[Salary]),Table1[[#This Row],[Salary]]) -> 69450.99 | I5: =LOWER(TRIM(Table1[[#This Row],[Email]])) -> eva.davis@example.com | J5: =ABS(Table1[[#This Row],[Phone]]) -> 3476490784 | K5: =PROPER(TRIM(Table1[[#This Row],[Performance_Score]])) -> Good | L5: =Table1[[#This Row],[Remote_Work]] -> TRUE | M5: =PROPER(CONCATENATE(Table13[[#This Row],[First_Name]], Table13[[#This Row],[Last_Name]])) -> Evadavis | N5: =TEXT(G5,"mmm") -> Nov | O5: =TEXT(Table13[[#This Row],[Join_Date]],"yyyy") -> 2021 | P5: =LEFT('Main Project Raw Data'!E5,FIND("-",'Main Project Raw Data'!E5)-1) -> Admin | Q5: =RIGHT('Main Project Raw Data'!E5,LEN('Main Project Raw Data'!E5)-FIND("-",'Main Project Raw Data'!E5)) -> Nevada
A6: =TRIM(Table1[[#This Row],[Employee_ID]]) -> EMP1004 | B6: =PROPER(TRIM(Table1[[#This Row],[First_Name]])) -> Frank | C6: =PROPER(TRIM(Table1[[#This Row],[Last_Name]])) -> Williams | D6: =IF(Table1[[#This Row],[Age]]="",AVERAGE(Table1[Age]),Table1[[#This Row],[Age]]) -> 25 | E6: Cloud Tech-Florida | F6: Active | G6: =IF(ISNUMBER('Main Project Raw Data'!G6),'Main Project Raw Data'!G6,IF(ISNUMBER(SEARCH("/",'Main Project Raw Data'!G6)),DATE(RIGHT('Main Project Raw Data'!G6,4),LEFT('Main Project Raw Data'!G6,FIND("/",'Main Project Raw Data'!G6)-1),MID('Main Project Raw Data'!G6,FIND("/",'Main Project Raw Data'!G6)+1,2)),DATE(RIGHT('Main Project Raw Data'!G6,4),MID('Main Project Raw Data'!G6,4,2),LEFT('Main Project Raw Data'!G6,2)))) -> 44682 | H6: =IF(Table1[[#This Row],[Salary]]="",AVERAGE(Table1[Salary]),Table1[[#This Row],[Salary]]) -> 109324.61 | I6: =LOWER(TRIM(Table1[[#This Row],[Email]])) -> frank.williams@example.com | J6: =ABS(Table1[[#This Row],[Phone]]) -> 1586734256 | K6: =PROPER(TRIM(Table1[[#This Row],[Performance_Score]])) -> Poor | L6: =Table1[[#This Row],[Remote_Work]] -> FALSE | M6: =PROPER(CONCATENATE(Table13[[#This Row],[First_Name]], Table13[[#This Row],[Last_Name]])) -> Frankwilliams | N6: =TEXT(G6,"mmm") -> May | O6: =TEXT(Table13[[#This Row],[Join_Date]],"yyyy") -> 2022 | P6: =LEFT('Main Project Raw Data'!E6,FIND("-",'Main Project Raw Data'!E6)-1) -> Cloud Tech | Q6: =RIGHT('Main Project Raw Data'!E6,LEN('Main Project Raw Data'!E6)-FIND("-",'Main Project Raw Data'!E6)) -> Florida
A7: =TRIM(Table1[[#This Row],[Employee_ID]]) -> EMP1005 | B7: =PROPER(TRIM(Table1[[#This Row],[First_Name]])) -> Alice | C7: =PROPER(TRIM(Table1[[#This Row],[Last_Name]])) -> Garcia | D7: =IF(Table1[[#This Row],[Age]]="",AVERAGE(Table1[Age]),Table1[[#This Row],[Age]]) -> 40 | E7: Sales-Texas | F7: Inactive | G7: =IF(ISNUMBER('Main Project Raw Data'!G7),'Main Project Raw Data'!G7,IF(ISNUMBER(SEARCH("/",'Main Project Raw Data'!G7)),DATE(RIGHT('Main Project Raw Data'!G7,4),LEFT('Main Project Raw Data'!G7,FIND("/",'Main Project Raw Data'!G7)-1),MID('Main Project Raw Data'!G7,FIND("/",'Main Project Raw Data'!G7)+1,2)),DATE(RIGHT('Main Project Raw Data'!G7,4),MID('Main Project Raw Data'!G7,4,2),LEFT('Main Project Raw Data'!G7,2)))) -> 44110 | H7: =IF(Table1[[#This Row],[Salary]]="",AVERAGE(Table1[Salary]),Table1[[#This Row],[Salary]]) -> 88642.84 | I7: =LOWER(TRIM(Table1[[#This Row],[Email]])) -> alice.garcia@example.com | J7: =ABS(Table1[[#This Row],[Phone]]) -> 5409003485 | K7: =PROPER(TRIM(Table1[[#This Row],[Performance_Score]])) -> Good | L7: =Table1[[#This Row],[Remote_Work]] -> FALSE | M7: =PROPER(CONCATENATE(Table13[[#This Row],[First_Name]], Table13[[#This Row],[Last_Name]])) -> Alicegarcia | N7: =TEXT(G7,"mmm") -> Oct | O7: =TEXT(Table13[[#This Row],[Join_Date]],"yyyy") -> 2020 | P7: =LEFT('Main Project Raw Data'!E7,FIND("-",'Main Project Raw Data'!E7)-1) -> Sales | Q7: =RIGHT('Main Project Raw Data'!E7,LEN('Main Project Raw Data'!E7)-FIND("-",'Main Project Raw Data'!E7)) -> Texas
A8: =TRIM(Table1[[#This Row],[Employee_ID]]) -> EMP1006 | B8: =TRIM(Table1[[#This Row],[First_Name]]) -> Frank | C8: =TRIM(Table1[[#This Row],[Last_Name]]) -> Jones | D8: =IF(Table1[[#This Row],[Age]]="",AVERAGE(Table1[Age]),Table1[[#This Row],[Age]]) -> 32.484549 | E8: Admin-Nevada | F8: Active | G8: =IF(ISNUMBER('Main Project Raw Data'!G8),'Main Project Raw Data'!G8,IF(ISNUMBER(SEARCH("/",'Main Project Raw Data'!G8)),DATE(RIGHT('Main Project Raw Data'!G8,4),LEFT('Main Project Raw Data'!G8,FIND("/",'Main Project Raw Data'!G8)-1),MID('Main Project Raw Data'!G8,FIND("/",'Main Project Raw Data'!G8)+1,2)),DATE(RIGHT('Main Project Raw Data'!G8,4),MID('Main Project Raw Data'!G8,4,2),LEFT('Main Project Raw Data'!G8,2)))) -> 43894 | H8: =IF(Table1[[#This Row],[Salary]]="",AVERAGE(Table1[Salary]),Table1[[#This Row],[Salary]]) -> 96288.43 | I8: =LOWER(TRIM(Table1[[#This Row],[Email]])) -> frank.jones@example.com | J8: =ABS(Table1[[#This Row],[Phone]]) -> 4518376063 | K8: =PROPER(TRIM(Table1[[#This Row],[Performance_Score]])) -> Good | L8: =Table1[[#This Row],[Remote_Work]] -> FALSE | M8: =PROPER(CONCATENATE(Table13[[#This Row],[First_Name]], Table13[[#This Row],[Last_Name]])) -> Frankjones | N8: =TEXT(G8,"mmm") -> Mar | O8: =TEXT(Table13[[#This Row],[Join_Date]],"yyyy") -> 2020 | P8: =LEFT('Main Project Raw Data'!E8,FIND("-",'Main Project Raw Data'!E8)-1) -> Admin | Q8: =RIGHT('Main Project Raw Data'!E8,LEN('Main Project Raw Data'!E8)-FIND("-",'Main Project Raw Data'!E8)) -> Nevada
A9: =TRIM(Table1[[#This Row],[Employee_ID]]) -> EMP1007 | B9: =TRIM(Table1[[#This Row],[First_Name]]) -> Bob | C9: =TRIM(Table1[[#This Row],[Last_Name]]) -> Jones | D9: =IF(Table1[[#This Row],[Age]]="",AVERAGE(Table1[Age]),Table1[[#This Row],[Age]]) -> 30 | E9: Cloud Tech-Florida | F9: Inactive | G9: =IF(ISNUMBER('Main Project Raw Data'!G9),'Main Project Raw Data'!G9,IF(ISNUMBER(SEARCH("/",'Main Project Raw Data'!G9)),DATE(RIGHT('Main Project Raw Data'!G9,4),LEFT('Main Project Raw Data'!G9,FIND("/",'Main Project Raw Data'!G9)-1),MID('Main Project Raw Data'!G9,FIND("/",'Main Project Raw Data'!G9)+1,2)),DATE(RIGHT('Main Project Raw Data'!G9,4),MID('Main Project Raw Data'!G9,4,2),LEFT('Main Project Raw Data'!G9,2)))) -> 44759 | H9: =IF(Table1[[#This Row],[Salary]]="",AVERAGE(Table1[Salary]),Table1[[#This Row],[Salary]]) -> 94497.91 | I9: =LOWER(TRIM(Table1[[#This Row],[Email]])) -> bob.jones@example.com | J9: =ABS(Table1[[#This Row],[Phone]]) -> 4134327559 | K9: =PROPER(TRIM(Table1[[#This Row],[Performance_Score]])) -> Average | L9: =Table1[[#This Row],[Remote_Work]] -> TRUE | M9: =PROPER(CONCATENATE(Table13[[#This Row],[First_Name]], Table13[[#This Row],[Last_Name]])) -> Bobjones | N9: =TEXT(G9,"mmm") -> Jul | O9: =TEXT(Table13[[#This Row],[Join_Date]],"yyyy") -> 2022 | P9: =LEFT('Main Project Raw Data'!E9,FIND("-",'Main Project Raw Data'!E9)-1) -> Cloud Tech | Q9: =RIGHT('Main Project Raw Data'!E9,LEN('Main Project Raw Data'!E9)-FIND("-",'Main Project Raw Data'!E9)) -> Florida
A10: =TRIM(Table1[[#This Row],[Employee_ID]]) -> EMP1008 | B10: =TRIM(Table1[[#This Row],[First_Name]]) -> Frank | C10: =TRIM(Table1[[#This Row],[Last_Name]]) -> Davis | D10: =IF(Table1[[#This Row],[Age]]="",AVERAGE(Table1[Age]),Table1[[#This Row],[Age]]) -> 35 | E10: Admin-Nevada | F10: Inactive | G10: =IF(ISNUMBER('Main Project Raw Data'!G10),'Main Project Raw Data'!G10,IF(ISNUMBER(SEARCH("/",'Main Project Raw Data'!G10)),DATE(RIGHT('Main Project Raw Data'!G10,4),LEFT('Main Project Raw Data'!G10,FIND("/",'Main Project Raw Data'!G10)-1),MID('Main Project Raw Data'!G10,FIND("/",'Main Project Raw Data'!G10)+1,2)),DATE(RIGHT('Main Project Raw Data'!G10,4),MID('Main Project Raw Data'!G10,4,2),LEFT('Main Project Raw Data'!G10,2)))) -> 45150 | H10: =IF(Table1[[#This Row],[Salary]]="",AVERAGE(Table1[Salary]),Table1[[#This Row],[Salary]]) -> 115565.82 | I10: frank.davis@example.com | J10: =ABS(Table1[[#This Row],[Phone]]) -> 4177656123 | K10: =PROPER(TRIM(Table1[[#This Row],[Performance_Score]])) -> Excellent | L10: =Table1[[#This Row],[Remote_Work]] -> TRUE | M10: =PROPER(CONCATENATE(Table13[[#This Row],[First_Name]], Table13[[#This Row],[Last_Name]])) -> Frankdavis | N10: =TEXT(G10,"mmm") -> Aug | O10: =TEXT(Table13[[#This Row],[Join_Date]],"yyyy") -> 2023 | P10: =LEFT('Main Project Raw Data'!E10,FIND("-",'Main Project Raw Data'!E10)-1) -> Admin | Q10: =RIGHT('Main Project Raw Data'!E10,LEN('Main Project Raw Data'!E10)-FIND("-",'Main Project Raw Data'!E10)) -> Nevada
A11: =TRIM(Table1[[#This Row],[Employee_ID]]) -> EMP1009 | B11: =TRIM(Table1[[#This Row],[First_Name]]) -> Charlie | C11: =TRIM(Table1[[#This Row],[Last_Name]]) -> Johnson | D11: =IF(Table1[[#This Row],[Age]]="",AVERAGE(Table1[Age]),Table1[[#This Row],[Age]]) -> 32.484549 | E11: DevOps-New York | F11: Active | G11: =IF(ISNUMBER('Main Project Raw Data'!G11),'Main Project Raw Data'!G11,IF(ISNUMBER(SEARCH("/",'Main Project Raw Data'!G11)),DATE(RIGHT('Main Project Raw Data'!G11,4),LEFT('Main Project Raw Data'!G11,FIND("/",'Main Project Raw Data'!G11)-1),MID('Main Project Raw Data'!G11,FIND("/",'Main Project Raw Data'!G11)+1,2)),DATE(RIGHT('Main Project Raw Data'!G11,4),MID('Main Project Raw Data'!G11,4,2),LEFT('Main Project Raw Data'!G11,2)))) -> 44659 | H11: =IF(Table1[[#This Row],[Salary]]="",AVERAGE(Table1[Salary]),Table1[[#This Row],[Salary]]) -> 76561.88 | I11: charlie.johnson@example.com | J11: =ABS(Table1[[#This Row],[Phone]]) -> 8156985699 | K11: =PROPER(TRIM(Table1[[#This Row],[Performance_Score]])) -> Excellent | L11: =Table1[[#This Row],[Remote_Work]] -> TRUE | M11: =PROPER(CONCATENATE(Table13[[#This Row],[First_Name]], Table13[[#This Row],[Last_Name]])) -> Charliejohnson | N11: =TEXT(G11,"mmm") -> Apr | O11: =TEXT(Table13[[#This Row],[Join_Date]],"yyyy") -> 2022 | P11: =LEFT('Main Project Raw Data'!E11,FIND("-",'Main Project Raw Data'!E11)-1) -> DevOps | Q11: =RIGHT('Main Project Raw Data'!E11,LEN('Main Project Raw Data'!E11)-FIND("-",'Main Project Raw Data'!E11)) -> New York
A12: =TRIM(Table1[[#This Row],[Employee_ID]]) -> EMP1010 | B12: =TRIM(Table1[[#This Row],[First_Name]]) -> David | C12: =TRIM(Table1[[#This Row],[Last_Name]]) -> Williams | D12: =IF(Table1[[#This Row],[Age]]="",AVERAGE(Table1[Age]),Table1[[#This Row],[Age]]) -> 35 | E12: Cloud Tech-New York | F12: Active | G12: =IF(ISNUMBER('Main Project Raw Data'!G12),'Main Project Raw Data'!G12,IF(ISNUMBER(SEARCH("/",'Main Project Raw Data'!G12)),DATE(RIGHT('Main Project Raw Data'!G12,4),LEFT('Main Project Raw Data'!G12,FIND("/",'Main Project Raw Data'!G12)-1),MID('Main Project Raw Data'!G12,FIND("/",'Main Project Raw Data'!G12)+1,2)),DATE(RIGHT('Main Project Raw Data'!G12,4),MID('Main Project Raw Data'!G12,4,2),LEFT('Main Project Raw Data'!G12,2)))) -> 45450 | H12: =IF(Table1[[#This Row],[Salary]]="",AVERAGE(Table1[Salary]),Table1[[#This Row],[Salary]]) -> 72081.71 | I12: david.williams@example.com | J12: =ABS(Table1[[#This Row],[Phone]]) -> 2720634590 | K12: =PROPER(TRIM(Table1[[#This Row],[Performance_Score]])) -> Average | L12: =Table1[[#This Row],[Remote_Work]] -> FALSE | M12: =PROPER(CONCATENATE(Table13[[#This Row],[First_Name]], Table13[[#This Row],[Last_Name]])) -> Davidwilliams | N12: =TEXT(G12,"mmm") -> Jun | O12: =TEXT(Table13[[#This Row],[Join_Date]],"yyyy") -> 2024 | P12: =LEFT('Main Project Raw Data'!E12,FIND("-",'Main Project Raw Data'!E12)-1) -> Cloud Tech | Q12: =RIGHT('Main Project Raw Data'!E12,LEN('Main Project Raw Data'!E12)-FIND("-",'Main Project Raw Data'!E12)) -> New York
A13: =TRIM(Table1[[#This Row],[Employee_ID]]) -> EMP1011 | B13: =TRIM(Table1[[#This Row],[First_Name]]) -> David | C13: =TRIM(Table1[[#This Row],[Last_Name]]) -> Davis | D13: =IF(Table1[[#This Row],[Age]]="",AVERAGE(Table1[Age]),Table1[[#This Row],[Age]]) -> 32.484549 | E13: DevOps-California | F13: Active | G13: =IF(ISNUMBER('Main Project Raw Data'!G13),'Main Project Raw Data'!G13,IF(ISNUMBER(SEARCH("/",'Main Project Raw Data'!G13)),DATE(RIGHT('Main Project Raw Data'!G13,4),LEFT('Main Project Raw Data'!G13,FIND("/",'Main Project Raw Data'!G13)-1),MID('Main Project Raw Data'!G13,FIND("/",'Main Project Raw Data'!G13)+1,2)),DATE(RIGHT('Main Project Raw Data'!G13,4),MID('Main Project Raw Data'!G13,4,2),LEFT('Main Project Raw Data'!G13,2)))) -> 45025 | H13: =IF(Table1[[#This Row],[Salary]]="",AVERAGE(Table1[Salary]),Table1[[#This Row],[Salary]]) -> 84946.19 | I13: david.davis@example.com | J13: =ABS(Table1[[#This Row],[Phone]]) -> 1238296576 | K13: =PROPER(TRIM(Table1[[#This Row],[Performance_Score]])) -> Poor | L13: =Table1[[#This Row],[Remote_Work]] -> TRUE | M13: =PROPER(CONCATENATE(Table13[[#This Row],[First_Name]], Table13[[#This Row],[Last_Name]])) -> Daviddavis | N13: =TEXT(G13,"mmm") -> Apr | O13: =TEXT(Table13[[#This Row],[Join_Date]],"yyyy") -> 2023 | P13: =LEFT('Main Project Raw Data'!E13,FIND("-",'Main Project Raw Data'!E13)-1) -> DevOps | Q13: =RIGHT('Main Project Raw Data'!E13,LEN('Main Project Raw Data'!E13)-FIND("-",'Main Project Raw Data'!E13)) -> California
A14: =TRIM(Table1[[#This Row],[Employee_ID]]) -> EMP1012 | B14: =TRIM(Table1[[#This Row],[First_Name]]) -> Heidi | C14: =TRIM(Table1[[#This Row],[Last_Name]]) -> Williams | D14: =IF(Table1[[#This Row],[Age]]="",AVERAGE(Table1[Age]),Table1[[#This Row],[Age]]) -> 30 | E14: HR-New York | F14: Active | G14: =IF(ISNUMBER('Main Project Raw Data'!G14),'Main Project Raw Data'!G14,IF(ISNUMBER(SEARCH("/",'Main Project Raw Data'!G14)),DATE(RIGHT('Main Project Raw Data'!G14,4),LEFT('Main Project Raw Data'!G14,FIND("/",'Main Project Raw Data'!G14)-1),MID('Main Project Raw Data'!G14,FIND("/",'Main Project Raw Data'!G14)+1,2)),DATE(RIGHT('Main Project Raw Data'!G14,4),MID('Main Project Raw Data'!G14,4,2),LEFT('Main Project Raw Data'!G14,2)))) -> 45415 | H14: =IF(Table1[[#This Row],[Salary]]="",AVERAGE(Table1[Salary]),Table1[[#This Row],[Salary]]) -> 89295.77 | I14: heidi.williams@example.com | J14: =ABS(Table1[[#This Row],[Phone]]) -> 2429543164 | K14: =PROPER(TRIM(Table1[[#This Row],[Performance_Score]])) -> Excellent | L14: =Table1[[#This Row],[Remote_Work]] -> FALSE | M14: =PROPER(CONCATENATE(Table13[[#This Row],[First_Name]], Table13[[#This Row],[Last_Name]])) -> Heidiwilliams | N14: =TEXT(G14,"mmm") -> May | O14: =TEXT(Table13[[#This Row],[Join_Date]],"yyyy") -> 2024 | P14: =LEFT('Main Project Raw Data'!E14,FIND("-",'Main Project Raw Data'!E14)-1) -> HR | Q14: =RIGHT('Main Project Raw Data'!E14,LEN('Main Project Raw Data'!E14)-FIND("-",'Main Project Raw Data'!E14)) -> New York
A15: =TRIM(Table1[[#This Row],[Employee_ID]]) -> EMP1013 | B15: =TRIM(Table1[[#This Row],[First_Name]]) -> Grace | C15: =TRIM(Table1[[#This Row],[Last_Name]]) -> Williams | D15: =IF(Table1[[#This Row],[Age]]="",AVERAGE(Table1[Age]),Table1[[#This Row],[Age]]) -> 32.484549 | E15: Finance-California | F15: Active | G15: =IF(ISNUMBER('Main Project Raw Data'!G15),'Main Project Raw Data'!G15,IF(ISNUMBER(SEARCH("/",'Main Project Raw Data'!G15)),DATE(RIGHT('Main Project Raw Data'!G15,4),LEFT('Main Project Raw Data'!G15,FIND("/",'Main Project Raw Data'!G15)-1),MID('Main Project Raw Data'!G15,FIND("/",'Main Project Raw Data'!G15)+1,2)),DATE(RIGHT('Main Project Raw Data'!G15,4),MID('Main Project Raw Data'!G15,4,2),LEFT('Main Project Raw Data'!G15,2)))) -> 44114 | H15: =IF(Table1[[#This Row],[Salary]]="",AVERAGE(Table1[Salary]),Table1[[#This Row],[Salary]]) -> 85666.84 | I15: grace.williams@example.com | J15: =ABS(Table1[[#This Row],[Phone]]) -> 2669300892 | K15: =PROPER(TRIM(Table1[[#This Row],[Performance_Score]])) -> Good | L15: =Table1[[#This Row],[Remote_Work]] -> FALSE | M15: =PROPER(CONCATENATE(Table13[[#This Row],[First_Name]], Table13[[#This Row],[Last_Name]])) -> Gracewilliams | N15: =TEXT(G15,"mmm") -> Oct | O15: =TEXT(Table13[[#This Row],[Join_Date]],"yyyy") -> 2020 | P15: =LEFT('Main Project Raw Data'!E15,FIND("-",'Main Project Raw Data'!E15)-1) -> Finance | Q15: =RIGHT('Main Project Raw Data'!E15,LEN('Main Project Raw Data'!E15)-FIND("-",'Main Project Raw Data'!E15)) -> California
A16: =TRIM(Table1[[#This Row],[Employee_ID]]) -> EMP1014 | B16: =TRIM(Table1[[#This Row],[First_Name]]) -> Alice | C16: =TRIM(Table1[[#This Row],[Last_Name]]) -> Garcia | D16: =IF(Table1[[#This Row],[Age]]="",AVERAGE(Table1[Age]),Table1[[#This Row],[Age]]) -> 25 | E16: Admin-Nevada | F16: Active | G16: =IF(ISNUMBER('Main Project Raw Data'!G16),'Main Project Raw Data'!G16,IF(ISNUMBER(SEARCH("/",'Main Project Raw Data'!G16)),DATE(RIGHT('Main Project Raw Data'!G16,4),LEFT('Main Project Raw Data'!G16,FIND("/",'Main Project Raw Data'!G16)-1),MID('Main Project Raw Data'!G16,FIND("/",'Main Project Raw Data'!G16)+1,2)),DATE(RIGHT('Main Project Raw Data'!G16,4),MID('Main Project Raw Data'!G16,4,2),LEFT('Main Project Raw Data'!G16,2)))) -> 45571 | H16: =IF(Table1[[#This Row],[Salary]]="",AVERAGE(Table1[Salary]),Table1[[#This Row],[Salary]]) -> 97633.68 | I16: alice.garcia@example.com | J16: =ABS(Table1[[#This Row],[Phone]]) -> 1734206968 | K16: =PROPER(TRIM(Table1[[#This Row],[Performance_Score]])) -> Excellent | L16: =Table1[[#This Row],[Remote_Work]] -> TRUE | M16: =PROPER(CONCATENATE(Table13[[#This Row],[First_Name]], Table13[[#This Row],[Last_Name]])) -> Alicegarcia | N16: =TEXT(G16,"mmm") -> Oct | O16: =TEXT(Table13[[#This Row],[Join_Date]],"yyyy") -> 2024 | P16: =LEFT('Main Project Raw Data'!E16,FIND("-",'Main Project Raw Data'!E16)-1) -> Admin | Q16: =RIGHT('Main Project Raw Data'!E16,LEN('Main Project Raw Data'!E16)-FIND("-",'Main Project Raw Data'!E16)) -> Nevada
A17: =TRIM(Table1[[#This Row],[Employee_ID]]) -> EMP1015 | B17: =TRIM(Table1[[#This Row],[First_Name]]) -> Grace | C17: =TRIM(Table1[[#This Row],[Last_Name]]) -> Jones | D17: =IF(Table1[[#This Row],[Age]]="",AVERAGE(Table1[Age]),Table1[[#This Row],[Age]]) -> 40 | E17: Sales-Florida | F17: Pending | G17: =IF(ISNUMBER('Main Project Raw Data'!G17),'Main Project Raw Data'!G17,IF(ISNUMBER(SEARCH("/",'Main Project Raw Data'!G17)),DATE(RIGHT('Main Project Raw Data'!G17,4),LEFT('Main Project Raw Data'!G17,FIND("/",'Main Project Raw Data'!G17)-1),MID('Main Project Raw Data'!G17,FIND("/",'Main Project Raw Data'!G17)+1,2)),DATE(RIGHT('Main Project Raw Data'!G17,4),MID('Main Project Raw Data'!G17,4,2),LEFT('Main Project Raw Data'!G17,2)))) -> 44345 | H17: =IF(Table1[[#This Row],[Salary]]="",AVERAGE(Table1[Salary]),Table1[[#This Row],[Salary]]) -> 117975.49 | I17: grace.jones@example.com | J17: =ABS(Table1[[#This Row],[Phone]]) -> 4215291085 | K17: =PROPER(TRIM(Table1[[#This Row],[Performance_Score]])) -> Good | L17: =Table1[[#This Row],[Remote_Work]] -> TRUE | M17: =PROPER(CONCATENATE(Table13[[#This Row],[First_Name]], Table13[[#This Row],[Last_Name]])) -> Gracejones | N17: =TEXT(G17,"mmm") -> May | O17: =TEXT(Table13[[#This Row],[Join_Date]],"yyyy") -> 2021 | P17: =LEFT('Main Project Raw Data'!E17,FIND("-",'Main Project Raw Data'!E17)-1) -> Sales | Q17: =RIGHT('Main Project Raw Data'!E17,LEN('Main Project Raw Data'!E17)-FIND("-",'Main Project Raw Data'!E17)) -> Florida
A18: =TRIM(Table1[[#This Row],[Employee_ID]]) -> EMP1016 | B18: =TRIM(Table1[[#This Row],[First_Name]]) -> Alice | C18: =TRIM(Table1[[#This Row],[Last_Name]]) -> Brown | D18: =IF(Table1[[#This Row],[Age]]="",AVERAGE(Table1[Age]),Table1[[#This Row],[Age]]) -> 25 | E18: DevOps-Illinois | F18: Inactive | G18: =IF(ISNUMBER('Main Project Raw Data'!G18),'Main Project Raw Data'!G18,IF(ISNUMBER(SEARCH("/",'Main Project Raw Data'!G18)),DATE(RIGHT('Main Project Raw Data'!G18,4),LEFT('Main Project Raw Data'!G18,FIND("/",'Main Project Raw Data'!G18)-1),MID('Main Project Raw Data'!G18,FIND("/",'Main Project Raw Data'!G18)+1,2)),DATE(RIGHT('Main Project Raw Data'!G18,4),MID('Main Project Raw Data'!G18,4,2),LEFT('Main Project Raw Data'!G18,2)))) -> 45405 | H18: =IF(Table1[[#This Row],[Salary]]="",AVERAGE(Table1[Salary]),Table1[[#This Row],[Salary]]) -> 94867.33 | I18: alice.brown@example.com | J18: =ABS(Table1[[#This Row],[Phone]]) -> 7713334475 | K18: =PROPER(TRIM(Table1[[#This Row],[Performance_Score]])) -> Poor | L18: =Table1[[#This Row],[Remote_Work]] -> FALSE | M18: =PROPER(CONCATENATE(Table13[[#This Row],[First_Name]], Table13[[#This Row],[Last_Name]])) -> Alicebrown | N18: =TEXT(G18,"mmm") -> Apr | O18: =TEXT(Table13[[#This Row],[Join_Date]],"yyyy") -> 2024 | P18: =LEFT('Main Project Raw Data'!E18,FIND("-",'Main Project Raw Data'!E18)-1) -> DevOps | Q18: =RIGHT('Main Project Raw Data'!E18,LEN('Main Project Raw Data'!E18)-FIND("-",'Main Project Raw Data'!E18)) -> Illinois
A19: =TRIM(Table1[[#This Row],[Employee_ID]]) -> EMP1017 | B19: =TRIM(Table1[[#This Row],[First_Name]]) -> Grace | C19: =TRIM(Table1[[#This Row],[Last_Name]]) -> Garcia | D19: =IF(Table1[[#This Row],[Age]]="",AVERAGE(Table1[Age]),Table1[[#This Row],[Age]]) -> 30 | E19: Finance-Texas | F19: Pending | G19: =IF(ISNUMBER('Main Project Raw Data'!G19),'Main Project Raw Data'!G19,IF(ISNUMBER(SEARCH("/",'Main Project Raw Data'!G19)),DATE(RIGHT('Main Project Raw Data'!G19,4),LEFT('Main Project Raw Data'!G19,FIND("/",'Main Project Raw Data'!G19)-1),MID('Main Project Raw Data'!G19,FIND("/",'Main Project Raw Data'!G19)+1,2)),DATE(RIGHT('Main Project Raw Data'!G19,4),MID('Main Project Raw Data'!G19,4,2),LEFT('Main Project Raw Data'!G19,2)))) -> 45624 | H19: =IF(Table1[[#This Row],[Salary]]="",AVERAGE(Table1[Salary]),Table1[[#This Row],[Salary]]) -> 100377.65 | I19: grace.garcia@example.com | J19: =ABS(Table1[[#This Row],[Phone]]) -> 2639343625 | K19: =PROPER(TRIM(Table1[[#This Row],[Performance_Score]])) -> Average | L19: =Table1[[#This Row],[Remote_Work]] -> TRUE | M19: =PROPER(CONCATENATE(Table13[[#This Row],[First_Name]], Table13[[#This Row],[Last_Name]])) -> Gracegarcia | N19: =TEXT(G19,"mmm") -> Nov | O19: =TEXT(Table13[[#This Row],[Join_Date]],"yyyy") -> 2024 | P19: =LEFT('Main Project Raw Data'!E19,FIND("-",'Main Project Raw Data'!E19)-1) -> Finance | Q19: =RIGHT('Main Project Raw Data'!E19,LEN('Main Project Raw Data'!E19)-FIND("-",'Main Project Raw Data'!E19)) -> Texas
A20: =TRIM(Table1[[#This Row],[Employee_ID]]) -> EMP1018 | B20: =TRIM(Table1[[#This Row],[First_Name]]) -> Charlie | C20: =TRIM(Table1[[#This Row],[Last_Name]]) -> Garcia | D20: =IF(Table1[[#This Row],[Age]]="",AVERAGE(Table1[Age]),Table1[[#This Row],[Age]]) -> 32.484549 | E20: Cloud Tech-Nevada | F20: Inactive | G20: =IF(ISNUMBER('Main Project Raw Data'!G20),'Main Project Raw Data'!G20,IF(ISNUMBER(SEARCH("/",'Main Project Raw Data'!G20)),DATE(RIGHT('Main Project Raw Data'!G20,4),LEFT('Main Project Raw Data'!G20,FIND("/",'Main Project Raw Data'!G20)-1),MID('Main Project Raw Data'!G20,FIND("/",'Main Project Raw Data'!G20)+1,2)),DATE(RIGHT('Main Project Raw Data'!G20,4),MID('Main Project Raw Data'!G20,4,2),LEFT('Main Project Raw Data'!G20,2)))) -> 45554 | H20: =IF(Table1[[#This Row],[Salary]]="",AVERAGE(Table1[Salary]),Table1[[#This Row],[Salary]]) -> 94726.46 | I20: charlie.garcia@example.com | J20: =ABS(Table1[[#This Row],[Phone]]) -> 2044397358 | K20: =PROPER(TRIM(Table1[[#This Row],[Performance_Score]])) -> Excellent | L20: =Table1[[#This Row],[Remote_Work]] -> FALSE | M20: =PROPER(CONCATENATE(Table13[[#This Row],[First_Name]], Table13[[#This Row],[Last_Name]])) -> Charliegarcia | N20: =TEXT(G20,"mmm") -> Sep | O20: =TEXT(Table13[[#This Row],[Join_Date]],"yyyy") -> 2024 | P20: =LEFT('Main Project Raw Data'!E20,FIND("-",'Main Project Raw Data'!E20)-1) -> Cloud Tech | Q20: =RIGHT('Main Project Raw Data'!E20,LEN('Main Project Raw Data'!E20)-FIND("-",'Main Project Raw Data'!E20)) -> Nevada
A21: =TRIM(Table1[[#This Row],[Employee_ID]]) -> EMP1019 | B21: =TRIM(Table1[[#This Row],[First_Name]]) -> Charlie | C21: =TRIM(Table1[[#This Row],[Last_Name]]) -> Williams | D21: =IF(Table1[[#This Row],[Age]]="",AVERAGE(Table1[Age]),Table1[[#This Row],[Age]]) -> 35 | E21: Admin-Illinois | F21: Pending | G21: =IF(ISNUMBER('Main Project Raw Data'!G21),'Main Project Raw Data'!G21,IF(ISNUMBER(SEARCH("/",'Main Project Raw Data'!G21)),DATE(RIGHT('Main Project Raw Data'!G21,4),LEFT('Main Project Raw Data'!G21,FIND("/",'Main Project Raw Data'!G21)-1),MID('Main Project Raw Data'!G21,FIND("/",'Main Project Raw Data'!G21)+1,2)),DATE(RIGHT('Main Project Raw Data'!G21,4),MID('Main Project Raw Data'!G21,4,2),LEFT('Main Project Raw Data'!G21,2)))) -> 43862 | H21: =IF(Table1[[#This Row],[Salary]]="",AVERAGE(Table1[Salary]),Table1[[#This Row],[Salary]]) -> 91926.12 | I21: charlie.williams@example.com | J21: =ABS(Table1[[#This Row],[Phone]]) -> 7107256365 | K21: =PROPER(TRIM(Table1[[#This Row],[Performance_Score]])) -> Average | L21: =Table1[[#This Row],[Remote_Work]] -> TRUE | M21: =PROPER(CONCATENATE(Table13[[#This Row],[First_Name]], Table13[[#This Row],[Last_Name]])) -> Charliewilliams | N21: =TEXT(G21,"mmm") -> Feb | O21: =TEXT(Table13[[#This Row],[Join_Date]],"yyyy") -> 2020 | P21: =LEFT('Main Project Raw Data'!E21,FIND("-",'Main Project Raw Data'!E21)-1) -> Admin | Q21: =RIGHT('Main Project Raw Data'!E21,LEN('Main Project Raw Data'!E21)-FIND("-",'Main Project Raw Data'!E21)) -> Illinois
... A1021: =TRIM(Table1[[#This Row],[Employee_ID]]) -> EMP2019 | B1021: =TRIM(Table1[[#This Row],[First_Name]]) -> Heidi | C1021: =TRIM(Table1[[#This Row],[Last_Name]]) -> Jones | D1021: =IF(Table1[[#This Row],[Age]]="",AVERAGE(Table1[Age]),Table1[[#This Row],[Age]]) -> 30 | E1021: DevOps-Illinois | F1021: Pending | G1021: =IF(ISNUMBER('Main Project Raw Data'!G1021),'Main Project Raw Data'!G1021,IF(ISNUMBER(SEARCH("/",'Main Project Raw Data'!G1021)),DATE(RIGHT('Main Project Raw Data'!G1021,4),LEFT('Main Project Raw Data'!G1021,FIND("/",'Main Project Raw Data'!G1021)-1),MID('Main Project Raw Data'!G1021,FIND("/",'Main Project Raw Data'!G1021)+1,2)),DATE(RIGHT('Main Project Raw Data'!G1021,4),MID('Main Project Raw Data'!G1021,4,2),LEFT('Main Project Raw Data'!G1021,2)))) -> 44249 | H1021: =IF(Table1[[#This Row],[Salary]]="",AVERAGE(Table1[Salary]),Table1[[#This Row],[Salary]]) -> 77764.24 | I1021: heidi.jones@example.com | J1021: =ABS(Table1[[#This Row],[Phone]]) -> 7629745492 | K1021: =PROPER(TRIM(Table1[[#This Row],[Performance_Score]])) -> Average | L1021: =Table1[[#This Row],[Remote_Work]] -> FALSE | M1021: =PROPER(CONCATENATE(Table13[[#This Row],[First_Name]], Table13[[#This Row],[Last_Name]])) -> Heidijones | N1021: =TEXT(G1021,"mmm") -> Feb | O1021: =TEXT(Table13[[#This Row],[Join_Date]],"yyyy") -> 2021 | P1021: =LEFT('Main Project Raw Data'!E1021,FIND("-",'Main Project Raw Data'!E1021)-1) -> DevOps | Q1021: =RIGHT('Main Project Raw Data'!E1021,LEN('Main Project Raw Data'!E1021)-FIND("-",'Main Project Raw Data'!E1021)) -> Illinois
